Workbook

Sheet Raw Data
A1: Order ID | B1: Order Date | C1: Region | D1: Salesperson | E1: Product | F1: Category | G1: Quantity | H1: Unit Price | I1: Customer | J1: Payment Method
A2: ORD0001 | B2: 45760 | C2: West | D2: Aarav Sharma | E2: Monitor | F2: Electronics | G2: 5 | H2: 16700 | I2: Royal Stores | J2: Bank Transfer
A3: ORD0002 | B3: 46006 | C3: West | D3: Priya Nair | E3: Webcam | F3: Electronics | G3: 1 | H3: 4260 | I3: Prime Distributors | J3: UPI
A4: ORD0003 | B4: 45928 | C4: West | D4: Ananya Rao | E4: Mouse | F4: Accessories | G4: 1 | H4: 760 | I4: Lotus Infotech | J4: UPI
A5: ORD0004 | B5: 45764 | C5: East | D5: Rahul Verma | E5: Headphones | F5: Accessories | G5: 4 | H5: 2420 | I5: Prime Distributors | J5: Cash
A6: ORD0005 | B6: 45729 | C6: West | D6: Aarav Sharma | E6: Keyboard | F6: Accessories | G6: 2 | H6: 1620 | I6: Vertex Consulting | J6: Bank Transfer
A7: ORD0006 | B7: 45846 | C7: West | D7: Sneha Reddy | E7: Laptop | F7: Electronics | G7: 5 | H7: 58140 | I7: City Mart | J7: Cash
A8: ORD0007 | B8: 45678 | C8: South | D8: Ananya Rao | E8: Tablet | F8: Electronics | G8: 1 | H8: 30650 | I8: Royal Stores | J8: Card
A9: ORD0008 | B9: 45760 | C9: North | D9: Sneha Reddy | E9: Printer | F9: Office Equipment | G9: 1 | H9: 12360 | I9: Bright Solutions | J9: Cash
A10: ORD0009 | B10: 45779 | C10: West | D10: Rahul Verma | E10: Laptop | F10: Electronics | G10: 2 | H10: 51470 | I10: Quantum Labs | J10: Cash
A11: ORD0010 | B11: 45872 | C11: South | D11: Ananya Rao | E11: Laptop | F11: Electronics | G11: 1 | H11: 56500 | I11: Future Systems | J11: Card
A12: ORD0011 | B12: 45988 | C12: East | D12: Priya Nair | E12: Keyboard | F12: Accessories | G12: 3 | H12: 1620 | I12: ABC Technologies | J12: Cash
A13: ORD0012 | B13: 45745 | C13: West | D13: Rahul Verma | E13: Laptop | F13: Electronics | G13: 2 | H13: 52030 | I13: Delta Services | J13: Bank Transfer
... A66: ORD0065 | B66: 45711 | C66: West | D66: Vikram Singh | E66: Keyboard | F66: Accessories | G66: 3 | H66: 1630 | I66: Orbit Solutions | J66: UPI
A67: ORD0066 | B67: 45763 | C67: East | D67: Vikram Singh | E67: Monitor | F67: Electronics | G67: 5 | H67: 19360 | J67: Bank Transfer
A68: ORD0067 | B68: 45917 | C68: South | D68: Aarav Sharma | E68: Office Chair | F68: Furniture | G68: 1 | H68: 7920 | I68: Kaveri Enterprises | J68: UPI
A69: ORD0068 | B69: 45967 | C69: East | D69: Aarav Sharma | E69: Webcam | F69: Electronics | G69: 10 | H69: 4920 | I69: Metro Supplies | J69: UPI
A70: ORD0069 | B70: 45848 | C70: North | D70: Vikram Singh | E70: Monitor | F70: Electronics | G70: 10 | H70: 17690 | I70: Prime Distributors | J70: Bank Transfer
A71: ORD0070 | B71: 45875 | C71: North | D71: Ananya Rao | E71: Printer | F71: Office Equipment | G71: 1 | H71: 12080 | I71: City Mart | J71: UPI
A72: ORD0071 | B72: 45701 | C72: South | D72: Priya Nair | E72: Desk | F72: Furniture | G72: 2 | H72: 9410 | I72: Sunrise Ltd | J72: UPI
A73: ORD0072 | B73: 45819 | C73: East | D73: Vikram Singh | E73: Headphones | F73: Accessories | G73: 10 | H73: 2310 | I73: Metro Supplies | J73: Cash
A74: ORD0073 | B74: 45859 | C74: South | D74: Sneha Reddy | E74: Laptop | F74: Electronics | G74: 1 | H74: 57830 | I74: Horizon Ltd | J74: Bank Transfer
A75: ORD0074 | B75: 45927 | C75: East | D75: Rahul Verma | E75: Webcam | F75: Electronics | G75: 1 | H75: 4480 | I75: Royal Stores | J75: Cash
A76: ORD0075 | B76: 46008 | C76: South | D76: Ananya Rao | E76: Laptop | F76: Electronics | G76: 3 | H76: 60150 | I76: Quantum Labs | J76: Cash
A77: ORD0076 | B77: 45961 | C77: South | D77: Rahul Verma | E77: Desk | F77: Furniture | G77: 2 | H77: 9220 | I77: Sunrise Ltd | J77: Bank Transfer
A78: ORD0077 | B78: 45928 | C78: South | D78: Priya Nair | E78: Printer | F78: Office Equipment | G78: 1 | H78: 11640 | I78: Orbit Solutions | J78: Bank Transfer
A79: ORD0078 | B79: 45872 | C79: South | D79: Aarav Sharma | E79: Keyboard | F79: Accessories | G79: 1 | H79: 1450 | I79: Orbit Solutions | J79: Cash
... A92: ORD0091 | B92: 45698 | C92: East | D92: Aarav Sharma | E92: Monitor | F92: Electronics | G92: 3 | H92: 18120 | I92: Evergreen Pvt Ltd | J92: Cash
A93: ORD0092 | B93: 45814 | C93: East | D93: Ananya Rao | E93: Webcam | F93: Electronics | G93: 4 | H93: 4340 | I93: Lotus Infotech
A94: ORD0093 | B94: 45672 | C94: South | D94: Rahul Verma | E94: Laptop | F94: Electronics | G94: 2 | H94: 54710 | I94: Innovate Corp | J94: UPI
A95: ORD0094 | B95: 45958 | C95: South | D95: Aarav Sharma | E95: Monitor | F95: Electronics | G95: 2 | H95: 18130 | I95: Lotus Infotech | J95: Bank Transfer
A96: ORD0095 | B96: 45722 | C96: West | D96: Priya Nair | E96: Webcam | F96: Electronics | G96: 10 | H96: 4350 | I96: Bright Solutions | J96: Bank Transfer
A97: ORD0096 | B97: 46002 | C97: North | D97: Vikram Singh | E97: Office Chair | F97: Furniture | G97: 3 | H97: 7660 | I97: Future Systems | J97: Card
A98: ORD0097 | B98: 45984 | C98: South | D98: Ananya Rao | E98: Desk | F98: Furniture | G98: 2 | H98: 9630 | I98: Innovate Corp | J98: Bank Transfer
A99: ORD0098 | B99: 45666 | C99: North | D99: Sneha Reddy | E99: Keyboard | F99: Accessories | G99: 1 | H99: 1360 | I99: Future Systems | J99: Card
A100: ORD0099 | B100: 46001 | C100: South | D100: Aarav Sharma | E100: Mouse | F100: Accessories | G100: 2 | H100: 720 | I100: Future Systems | J100: Bank Transfer
A101: ORD0100 | B101: 45786 | C101: West | D101: Priya Nair | E101: Tablet | F101: Electronics | G101: 1 | H101: 28320 | I101: Sunrise Ltd | J101: UPI
A102: ORD0101 | B102: 45793 | C102: West | D102: Rahul Verma | E102: Headphones | F102: Accessories | G102: 3 | H102: 2730 | I102: Vertex Consulting | J102: UPI
A103: ORD0102 | B103: 45720 | C103: North | D103: Priya Nair | E103: Mouse | F103: Accessories | G103: 1 | H103: 800 | I103: Nova Business | J103: Cash
A104: ORD0103 | B104: 45796 | C104: East | D104: Sneha Reddy | E104: Printer | F104: Office Equipment | G104: 2 | H104: 12010 | I104: Metro Supplies | J104: Bank Transfer
...

Sheet Cleaned Data
A1: Order ID | B1: Order Date | C1: Region | D1: Salesperson | E1: Product | F1: Category | G1: Quantity | H1: Unit Price | I1: Customer | J1: Payment Method | K1: Sales | L1: Discount | M1: Net Sales | N1: Sales Category | O1: Month | P1: Month No | Q1: Year | R1: Quarter
A2: ORD0001 | B2: 45760 | C2: West | D2: Aarav Sharma | E2: Monitor | F2: Electronics | G2: 5 | H2: 16700 | I2: Royal Stores | J2: Bank Transfer | K2: =G2*H2 -> 83500 | L2: =IF(K2>=50000,10%,5%) -> 0.1 | M2: U | N2: =_xludf.IFS(M2>=100000,"Excellent",M2>=50000,"Good",M2>=10000,"Average",TRUE,"Low") -> #NAME? | O2: =TEXT(B2,"mmmm") -> April | P2: =MONTH(B2) -> 4 | Q2: =YEAR(B2) -> 2025 | R2: ="Q"&ROUNDUP(MONTH(B2)/3,0) -> Q2
A3: ORD0002 | B3: 46006 | C3: West | D3: Priya Nair | E3: Webcam | F3: Electronics | G3: 1 | H3: 4260 | I3: Prime Distributors | J3: Upi | K3: =G3*H3 -> 4260 | L3: =IF(K3>=50000,10%,5%) -> 0.05 | M3: =K3*(1-L3) -> 4047 | N3: =_xludf.IFS(M3>=100000,"Excellent",M3>=50000,"Good",M3>=10000,"Average",TRUE,"Low") -> #NAME? | O3: =TEXT(B3,"mmmm") -> December | P3: =MONTH(B3) -> 12 | Q3: =YEAR(B3) -> 2025 | R3: ="Q"&ROUNDUP(MONTH(B3)/3,0) -> Q4
A4: ORD0003 | B4: 45928 | C4: West | D4: Ananya Rao | E4: Mouse | F4: Accessories | G4: 1 | H4: 760 | I4: Lotus Infotech | J4: Upi | K4: =G4*H4 -> 760 | L4: =IF(K4>=50000,10%,5%) -> 0.05 | M4: =K4*(1-L4) -> 722 | N4: =_xludf.IFS(M4>=100000,"Excellent",M4>=50000,"Good",M4>=10000,"Average",TRUE,"Low") -> #NAME? | O4: =TEXT(B4,"mmmm") -> September | P4: =MONTH(B4) -> 9 | Q4: =YEAR(B4) -> 2025 | R4: ="Q"&ROUNDUP(MONTH(B4)/3,0) -> Q3
A5: ORD0004 | B5: 45764 | C5: East | D5: Rahul Verma | E5: Headphones | F5: Accessories | G5: 4 | H5: 2420 | I5: Prime Distributors | J5: Cash | K5: =G5*H5 -> 9680 | L5: =IF(K5>=50000,10%,5%) -> 0.05 | M5: =K5*(1-L5) -> 9196 | N5: =_xludf.IFS(M5>=100000,"Excellent",M5>=50000,"Good",M5>=10000,"Average",TRUE,"Low") -> #NAME? | O5: =TEXT(B5,"mmmm") -> April | P5: =MONTH(B5) -> 4 | Q5: =YEAR(B5) -> 2025 | R5: ="Q"&ROUNDUP(MONTH(B5)/3,0) -> Q2
A6: ORD0005 | B6: 45729 | C6: West | D6: Aarav Sharma | E6: Keyboard | F6: Accessories | G6: 2 | H6: 1620 | I6: Vertex Consulting | J6: Bank Transfer | K6: =G6*H6 -> 3240 | L6: =IF(K6>=50000,10%,5%) -> 0.05 | M6: =K6*(1-L6) -> 3078 | N6: =_xludf.IFS(M6>=100000,"Excellent",M6>=50000,"Good",M6>=10000,"Average",TRUE,"Low") -> #NAME? | O6: =TEXT(B6,"mmmm") -> March | P6: =MONTH(B6) -> 3 | Q6: =YEAR(B6) -> 2025 | R6: ="Q"&ROUNDUP(MONTH(B6)/3,0) -> Q1
A7: ORD0006 | B7: 45846 | C7: West | D7: Sneha Reddy | E7: Laptop | F7: Electronics | G7: 5 | H7: 58140 | I7: City Mart | J7: Cash | K7: =G7*H7 -> 290700 | L7: =IF(K7>=50000,10%,5%) -> 0.1 | M7: =K7*(1-L7) -> 261630 | N7: =_xludf.IFS(M7>=100000,"Excellent",M7>=50000,"Good",M7>=10000,"Average",TRUE,"Low") -> #NAME? | O7: =TEXT(B7,"mmmm") -> July | P7: =MONTH(B7) -> 7 | Q7: =YEAR(B7) -> 2025 | R7: ="Q"&ROUNDUP(MONTH(B7)/3,0) -> Q3
A8: ORD0007 | B8: 45678 | C8: South | D8: Ananya Rao | E8: Tablet | F8: Electronics | G8: 1 | H8: 30650 | I8: Royal Stores | J8: Card | K8: =G8*H8 -> 30650 | L8: =IF(K8>=50000,10%,5%) -> 0.05 | M8: =K8*(1-L8) -> 29117.5 | N8: =_xludf.IFS(M8>=100000,"Excellent",M8>=50000,"Good",M8>=10000,"Average",TRUE,"Low") -> #NAME? | O8: =TEXT(B8,"mmmm") -> January | P8: =MONTH(B8) -> 1 | Q8: =YEAR(B8) -> 2025 | R8: ="Q"&ROUNDUP(MONTH(B8)/3,0) -> Q1
A9: ORD0008 | B9: 45760 | C9: North | D9: Sneha Reddy | E9: Printer | F9: Office Equipment | G9: 1 | H9: 12360 | I9: Bright Solutions | J9: Cash | K9: =G9*H9 -> 12360 | L9: =IF(K9>=50000,10%,5%) -> 0.05 | M9: =K9*(1-L9) -> 11742 | N9: =_xludf.IFS(M9>=100000,"Excellent",M9>=50000,"Good",M9>=10000,"Average",TRUE,"Low") -> #NAME? | O9: =TEXT(B9,"mmmm") -> April | P9: =MONTH(B9) -> 4 | Q9: =YEAR(B9) -> 2025 | R9: ="Q"&ROUNDUP(MONTH(B9)/3,0) -> Q2
A10: ORD0009 | B10: 45779 | C10: West | D10: Rahul Verma | E10: Laptop | F10: Electronics | G10: 2 | H10: 51470 | I10: Quantum Labs | J10: Cash | K10: =G10*H10 -> 102940 | L10: =IF(K10>=50000,10%,5%) -> 0.1 | M10: =K10*(1-L10) -> 92646 | N10: =_xludf.IFS(M10>=100000,"Excellent",M10>=50000,"Good",M10>=10000,"Average",TRUE,"Low") -> #NAME? | O10: =TEXT(B10,"mmmm") -> May | P10: =MONTH(B10) -> 5 | Q10: =YEAR(B10) -> 2025 | R10: ="Q"&ROUNDUP(MONTH(B10)/3,0) -> Q2
A11: ORD0010 | B11: 45872 | C11: South | D11: Ananya Rao | E11: Laptop | F11: Electronics | G11: 1 | H11: 56500 | I11: Future Systems | J11: Card | K11: =G11*H11 -> 56500 | L11: =IF(K11>=50000,10%,5%) -> 0.1 | M11: =K11*(1-L11) -> 50850 | N11: =_xludf.IFS(M11>=100000,"Excellent",M11>=50000,"Good",M11>=10000,"Average",TRUE,"Low") -> #NAME? | O11: =TEXT(B11,"mmmm") -> August | P11: =MONTH(B11) -> 8 | Q11: =YEAR(B11) -> 2025 | R11: ="Q"&ROUNDUP(MONTH(B11)/3,0) -> Q3
A12: ORD0011 | B12: 45988 | C12: East | D12: Priya Nair | E12: Keyboard | F12: Accessories | G12: 3 | H12: 1620 | I12: ABC Technologies | J12: Cash | K12: =G12*H12 -> 4860 | L12: =IF(K12>=50000,10%,5%) -> 0.05 | M12: =K12*(1-L12) -> 4617 | N12: =_xludf.IFS(M12>=100000,"Excellent",M12>=50000,"Good",M12>=10000,"Average",TRUE,"Low") -> #NAME? | O12: =TEXT(B12,"mmmm") -> November | P12: =MONTH(B12) -> 11 | Q12: =YEAR(B12) -> 2025 | R12: ="Q"&ROUNDUP(MONTH(B12)/3,0) -> Q4
A13: ORD0012 | B13: 45745 | C13: West | D13: Rahul Verma | E13: Laptop | F13: Electronics | G13: 2 | H13: 52030 | I13: Delta Services | J13: Bank Transfer | K13: =G13*H13 -> 104060 | L13: =IF(K13>=50000,10%,5%) -> 0.1 | M13: =K13*(1-L13) -> 93654 | N13: =_xludf.IFS(M13>=100000,"Excellent",M13>=50000,"Good",M13>=10000,"Average",TRUE,"Low") -> #NAME? | O13: =TEXT(B13,"mmmm") -> March | P13: =MONTH(B13) -> 3 | Q13: =YEAR(B13) -> 2025 | R13: ="Q"&ROUNDUP(MONTH(B13)/3,0) -> Q1
A14: ORD0013 | B14: 45757 | C14: South | D14: Vikram Singh | E14: Laptop | F14: Electronics | G14: 1 | H14: 60440 | I14: Nova Business | J14: Upi | K14: =G14*H14 -> 60440 | L14: =IF(K14>=50000,10%,5%) -> 0.1 | M14: =K14*(1-L14) -> 54396 | N14: =_xludf.IFS(M14>=100000,"Excellent",M14>=50000,"Good",M14>=10000,"Average",TRUE,"Low") -> #NAME? | O14: =TEXT(B14,"mmmm") -> April | P14: =MONTH(B14) -> 4 | Q14: =YEAR(B14) -> 2025 | R14: ="Q"&ROUNDUP(MONTH(B14)/3,0) -> Q2
... A251: ORD0250 | B251: 45696 | C251: South | D251: Sneha Reddy | E251: Headphones | F251: Accessories | G251: 2 | H251: 2540 | I251: Bright Solutions | J251: Card | K251: =G251*H251 -> 5080 | L251: =IF(K251>=50000,10%,5%) -> 0.05 | M251: =K251*(1-L251) -> 4826 | N251: =_xludf.IFS(M251>=100000,"Excellent",M251>=50000,"Good",M251>=10000,"Average",TRUE,"Low") -> #NAME? | O251: =TEXT(B251,"mmmm") -> February | P251: =MONTH(B251) -> 2 | Q251: =YEAR(B251) -> 2025 | R251: ="Q"&ROUNDUP(MONTH(B251)/3,0) -> Q1

Sheet Analysis
A1: Excel Data Analysis & Reporting
A2: Formula-based analysis of cleaned sales data
A4: Total Sales | B4: =SUM('Cleaned Data'!K2:K251) -> 11034150
A5: Total Net Sales | B5: =SUM('Cleaned Data'!M2:M251) -> 9984970
A6: Total Orders | B6: =COUNTA('Cleaned Data'!A2:A251) -> 250
A7: Average Net Sale | B7: =AVERAGE('Cleaned Data'!M2:M251) -> 40100.281
A8: Highest Net Sale | B8: =MAX('Cleaned Data'!M2:M251) -> 541440
A9: Lowest Net Sale | B9: =MIN('Cleaned Data'!M2:M251) -> 684
A11: SUMIFS / COUNTIFS Analysis | E11: Text & Date Function Examples
A12: Region | B12: Total Net Sales (SUMIFS) | C12: Order Count (COUNTIFS) | E12: TRIM | F12: Removes extra spaces | G12: =TRIM('Cleaned Data'!I2) -> Royal Stores
A13: East | B13: =SUMIFS('Cleaned Data'!$M$2:$M$251,'Cleaned Data'!$C$2:$C$251,A13) -> 1506802 | C13: =COUNTIFS('Cleaned Data'!$C$2:$C$251,A13) -> 51 | E13: UPPER | F13: Converts text to uppercase | G13: =UPPER('Cleaned Data'!C2) -> WEST
A14: North | B14: =SUMIFS('Cleaned Data'!$M$2:$M$251,'Cleaned Data'!$C$2:$C$251,A14) -> 3269418.5 | C14: =COUNTIFS('Cleaned Data'!$C$2:$C$251,A14) -> 75 | E14: LEFT | F14: Extracts first 3 characters | G14: =LEFT('Cleaned Data'!A2,3) -> ORD
A15: South | B15: =SUMIFS('Cleaned Data'!$M$2:$M$251,'Cleaned Data'!$C$2:$C$251,A15) -> 2454753 | C15: =COUNTIFS('Cleaned Data'!$C$2:$C$251,A15) -> 65 | E15: TEXT | F15: Returns month name | G15: =TEXT('Cleaned Data'!B2,"mmmm") -> April
A16: West | B16: =SUMIFS('Cleaned Data'!$M$2:$M$251,'Cleaned Data'!$C$2:$C$251,A16) -> 2753996.5 | C16: =COUNTIFS('Cleaned Data'!$C$2:$C$251,A16) -> 59 | E16: MONTH | F16: Returns month number | G16: =MONTH('Cleaned Data'!B2) -> 4
E17: YEAR | F17: Returns year | G17: =YEAR('Cleaned Data'!B2) -> 2025
A19: IF / IFS Classification
A20: IF formula | B20: =IF('Cleaned Data'!M2>=50000,"High","Low") -> High
A21: IFS formula | B21: =_xludf.IFS('Cleaned Data'!M2>=100000,"Excellent",'Cleaned Data'!M2>=50000,"Good",'Cleaned Data'!M2>=10000,"Average",TRUE,"Low") -> #NAME?

Sheet Pivot Analysis
A1: Pivot Analysis / Summary Tables
A3: Sales by Region | F3: Sales by Category
A4: Region | B4: Net_Sales | C4: Orders | D4: Quantity | F4: Category | G4: Net_Sales | H4: Orders
A5: East | B5: =SUMIFS('Cleaned Data'!$M$2:$M$251,'Cleaned Data'!$C$2:$C$251,A5) -> 1506802 | C5: =COUNTIFS('Cleaned Data'!$C$2:$C$251,A5) -> 51 | D5: =SUMIFS('Cleaned Data'!$G$2:$G$251,'Cleaned Data'!$C$2:$C$251,A5) -> 152 | F5: Accessories | G5: =SUMIFS('Cleaned Data'!$M$2:$M$251,'Cleaned Data'!$F$2:$F$251,F5) -> 405336.5 | H5: =COUNTIFS('Cleaned Data'!$F$2:$F$251,F5) -> 73
A6: North | B6: =SUMIFS('Cleaned Data'!$M$2:$M$251,'Cleaned Data'!$C$2:$C$251,A6) -> 3269418.5 | C6: =COUNTIFS('Cleaned Data'!$C$2:$C$251,A6) -> 75 | D6: =SUMIFS('Cleaned Data'!$G$2:$G$251,'Cleaned Data'!$C$2:$C$251,A6) -> 274 | F6: Electronics | G6: =SUMIFS('Cleaned Data'!$M$2:$M$251,'Cleaned Data'!$F$2:$F$251,F6) -> 7622397.5 | H6: =COUNTIFS('Cleaned Data'!$F$2:$F$251,F6) -> 105
A7: South | B7: =SUMIFS('Cleaned Data'!$M$2:$M$251,'Cleaned Data'!$C$2:$C$251,A7) -> 2454753 | C7: =COUNTIFS('Cleaned Data'!$C$2:$C$251,A7) -> 65 | D7: =SUMIFS('Cleaned Data'!$G$2:$G$251,'Cleaned Data'!$C$2:$C$251,A7) -> 191 | F7: Furniture | G7: =SUMIFS('Cleaned Data'!$M$2:$M$251,'Cleaned Data'!$F$2:$F$251,F7) -> 934425 | H7: =COUNTIFS('Cleaned Data'!$F$2:$F$251,F7) -> 41
A8: West | B8: =SUMIFS('Cleaned Data'!$M$2:$M$251,'Cleaned Data'!$C$2:$C$251,A8) -> 2753996.5 | C8: =COUNTIFS('Cleaned Data'!$C$2:$C$251,A8) -> 59 | D8: =SUMIFS('Cleaned Data'!$G$2:$G$251,'Cleaned Data'!$C$2:$C$251,A8) -> 188 | F8: Office Equipment | G8: =SUMIFS('Cleaned Data'!$M$2:$M$251,'Cleaned Data'!$F$2:$F$251,F8) -> 1022811 | H8: =COUNTIFS('Cleaned Data'!$F$2:$F$251,F8) -> 31
G9: =SUMIFS('Cleaned Data'!$M$2:$M$251,'Cleaned Data'!$F$2:$F$251,F9) -> 0 | H9: =COUNTIFS('Cleaned Data'!$F$2:$F$251,F9) -> 0
A12: Sales by Salesperson | F12: Monthly Net Sales
A13: Salesperson | B13: Net_Sales | C13: Orders | F13: Month | G13: Net_Sales
A14: Aarav Sharma | B14: =SUMIFS('Cleaned Data'!$M$2:$M$251,'Cleaned Data'!$D$2:$D$251,A14) -> 1464426.5 | C14: =COUNTIFS('Cleaned Data'!$D$2:$D$251,A14) -> 49 | F14: January | G14: =SUMIFS('Cleaned Data'!$M$2:$M$251,'Cleaned Data'!$O$2:$O$251,F14) -> 256757.5
A15: Ananya Rao | B15: =SUMIFS('Cleaned Data'!$M$2:$M$251,'Cleaned Data'!$D$2:$D$251,A15) -> 2133857 | C15: =COUNTIFS('Cleaned Data'!$D$2:$D$251,A15) -> 38 | F15: February | G15: =SUMIFS('Cleaned Data'!$M$2:$M$251,'Cleaned Data'!$O$2:$O$251,F15) -> 636433
A16: Priya Nair | B16: =SUMIFS('Cleaned Data'!$M$2:$M$251,'Cleaned Data'!$D$2:$D$251,A16) -> 1179533 | C16: =COUNTIFS('Cleaned Data'!$D$2:$D$251,A16) -> 42 | F16: March | G16: =SUMIFS('Cleaned Data'!$M$2:$M$251,'Cleaned Data'!$O$2:$O$251,F16) -> 489027
A17: Rahul Verma | B17: =SUMIFS('Cleaned Data'!$M$2:$M$251,'Cleaned Data'!$D$2:$D$251,A17) -> 2295900.5 | C17: =COUNTIFS('Cleaned Data'!$D$2:$D$251,A17) -> 41 | F17: April | G17: =SUMIFS('Cleaned Data'!$M$2:$M$251,'Cleaned Data'!$O$2:$O$251,F17) -> 827187
A18: Sneha Reddy | B18: =SUMIFS('Cleaned Data'!$M$2:$M$251,'Cleaned Data'!$D$2:$D$251,A18) -> 1270551.5 | C18: =COUNTIFS('Cleaned Data'!$D$2:$D$251,A18) -> 42 | F18: May | G18: =SUMIFS('Cleaned Data'!$M$2:$M$251,'Cleaned Data'!$O$2:$O$251,F18) -> 1435881
A19: Vikram Singh | B19: =SUMIFS('Cleaned Data'!$M$2:$M$251,'Cleaned Data'!$D$2:$D$251,A19) -> 1640701.5 | C19: =COUNTIFS('Cleaned Data'!$D$2:$D$251,A19) -> 38 | F19: June | G19: =SUMIFS('Cleaned Data'!$M$2:$M$251,'Cleaned Data'!$O$2:$O$251,F19) -> 689883.5
F20: July | G20: =SUMIFS('Cleaned Data'!$M$2:$M$251,'Cleaned Data'!$O$2:$O$251,F20) -> 1595135
F21: August | G21: =SUMIFS('Cleaned Data'!$M$2:$M$251,'Cleaned Data'!$O$2:$O$251,F21) -> 846861.5
F22: September | G22: =SUMIFS('Cleaned Data'!$M$2:$M$251,'Cleaned Data'!$O$2:$O$251,F22) -> 450805
F23: October | G23: =SUMIFS('Cleaned Data'!$M$2:$M$251,'Cleaned Data'!$O$2:$O$251,F23) -> 769029
F24: November | G24: =SUMIFS('Cleaned Data'!$M$2:$M$251,'Cleaned Data'!$O$2:$O$251,F24) -> 1231958
F25: December | G25: =SUMIFS('Cleaned Data'!$M$2:$M$251,'Cleaned Data'!$O$2:$O$251,F25) -> 756012.5

Sheet Dashboard
A1: SALES PERFORMANCE DASHBOARD
A2: Business summary based on the cleaned 2025 sales dataset
A4: Total Net Sales | D4: Total Orders | G4: Average Order Value | J4: Units Sold
A5: =SUM('Cleaned Data'!M2:M251) -> 9984970 | D5: =COUNTA('Cleaned Data'!A2:A251) -> 250 | G5: =AVERAGE('Cleaned Data'!M2:M251) -> 40100.281 | J5: =SUM('Cleaned Data'!G2:G251) -> 805
A38: Key Business Insights
A39: • North generated the highest net sales at ₹3,269,418, representing 32.5% of total net sales.
A40: • Electronics was the highest-revenue category with net sales of ₹7,697,548.
A41: • Rahul Verma generated the highest salesperson net sales at ₹2,295,900.
A42: • July recorded the highest monthly net sales at ₹1,595,135.
A43: • The dataset uses a tiered discount rule: 10% for sales of ₹50,000 or more and 5% otherwise.
A44: • Data cleaning standardized text fields, filled missing customer/payment information with explicit labels, and removed a duplicate Order ID before analysis.

Sheet Methodology
A1: Section | B1: Completed Work
A2: Dataset | B2: Structured sales/orders dataset with 251 raw rows and 250 unique Order IDs.
A3: Cleaning | B3: Trimmed/standardized text, standardized categories, filled missing customer/payment values, and removed duplicate Order ID.
A4: Table | B4: Cleaned data converted to Excel Table named SalesData with filters.
A5: Formulas | B5: Sales = Quantity × Unit Price; Discount and Net Sales calculated with formulas.
A6: IF/IFS | B6: Sales Category uses IFS; an IF example is documented on Analysis sheet.
A7: SUMIFS/COUNTIFS | B7: Regional sales and order counts calculated on Analysis sheet.
A8: Text functions | B8: TRIM, UPPER, LEFT and TEXT examples documented.
A9: Date functions | B9: MONTH, YEAR, TEXT and quarter logic included.
A10: Conditional formatting | B10: Color scale on Net Sales and data bars on Sales.
A11: Pivot analysis | B11: Regional, category, salesperson and monthly summary tables prepared for reporting.
A12: PivotCharts | B12: Dashboard contains region, category, monthly trend and salesperson charts.
A13: Reporting | B13: Dashboard contains KPI summary and data-supported business insights.
